<?xml version="1.0" ?>
<sdf version='1.7'>
  <world name='default'>
    <model name='ground_plane'>
      <static>1</static>
      <link name='link'>
        <collision name='collision'>
          <geometry>
            <plane>
              <normal>0 0 1</normal>
              <size>100 100</size>
            </plane>
          </geometry>
          <surface>
            <contact>
              <collide_bitmask>65535</collide_bitmask>
              <ode/>
            </contact>
            <friction>
              <ode>
                <mu>100</mu>
                <mu2>50</mu2>
              </ode>
              <torsional>
                <ode/>
              </torsional>
            </friction>
            <bounce/>
          </surface>
          <max_contacts>10</max_contacts>
        </collision>
        <visual name='visual'>
          <cast_shadows>0</cast_shadows>
          <geometry>
            <plane>
              <normal>0 0 1</normal>
              <size>100 100</size>
            </plane>
          </geometry>
          <material>
            <script>
              <uri>file://media/materials/scripts/gazebo.material</uri>
              <name>Gazebo/Grey</name>
            </script>
          </material>
        </visual>
        <self_collide>0</self_collide>
        <enable_wind>0</enable_wind>
        <kinematic>0</kinematic>
      </link>
    </model>
    <light name='sun' type='directional'>
      <cast_shadows>1</cast_shadows>
      <pose>0 0 10 0 -0 0</pose>
      <diffuse>0.8 0.8 0.8 1</diffuse>
      <specular>0.2 0.2 0.2 1</specular>
      <attenuation>
        <range>1000</range>
        <constant>0.9</constant>
        <linear>0.01</linear>
        <quadratic>0.001</quadratic>
      </attenuation>
      <direction>-0.5 0.1 -0.9</direction>
      <spot>
        <inner_angle>0</inner_angle>
        <outer_angle>0</outer_angle>
        <falloff>0</falloff>
      </spot>
    </light>
    <gui fullscreen='0'>
      <camera name='user_camera'>
        <pose>-1.03008 -7.89179 8.08376 0 0.969797 0.852001</pose>
        <view_controller>ortho</view_controller>
        <projection_type>orthographic</projection_type>
      </camera>
    </gui>
    <gravity>0 0 -9.81</gravity>
    <magnetic_field>6e-06 2.3e-05 -4.2e-05</magnetic_field>
    <atmosphere type='adiabatic'/>
    <physics type='ode'>
      <max_step_size>0.001</max_step_size>
      <real_time_factor>1</real_time_factor>
      <real_time_update_rate>1000</real_time_update_rate>
    </physics>
    <scene>
      <ambient>0.4 0.4 0.4 1</ambient>
      <background>0.7 0.7 0.7 1</background>
      <shadows>1</shadows>
    </scene>
    <wind/>
    <spherical_coordinates>
      <surface_model>EARTH_WGS84</surface_model>
      <latitude_deg>0</latitude_deg>
      <longitude_deg>0</longitude_deg>
      <elevation>0</elevation>
      <heading_deg>0</heading_deg>
    </spherical_coordinates>
    <model name='sink_furniture'>
      <joint name='base_joint' type='fixed'>
        <pose relative_to='__model__'>0 0 0.01 0 -0 0</pose>
        <parent>world</parent>
        <child>base_link</child>
      </joint>
      <link name='base_link'>
        <pose relative_to='base_joint'>0 0 0 0 -0 0</pose>
        <inertial>
          <pose>0.341839 0.004907 0.283661 0 -0 0</pose>
          <mass>80</mass>
          <inertia>
            <ixx>13.1429</ixx>
            <ixy>-0.127112</ixy>
            <ixz>-12.9504</ixz>
            <iyy>28.0802</iyy>
            <iyz>-0.0874853</iyz>
            <izz>17.9537</izz>
          </inertia>
        </inertial>
        <collision name='base_link_collision'>
          <pose>0 0 0 1.5714 -0 0</pose>
          <geometry>
            <mesh>
              <scale>100 100 100</scale>
              <uri>model://sink_furniture/meshes/kitchen_only_kitchen.obj</uri>
            </mesh>
          </geometry>
          <max_contacts>10</max_contacts>
          <surface>
            <contact>
              <ode/>
            </contact>
            <bounce/>
            <friction>
              <torsional>
                <ode/>
              </torsional>
              <ode/>
            </friction>
          </surface>
        </collision>
        <collision name='base_link_fixed_joint_lump__washer_link_collision_1'>
          <pose>-0.09 0.001 0.581 1.5714 -0 0</pose>
          <geometry>
            <mesh>
              <scale>1 1 1</scale>
              <uri>model://sink_furniture/meshes/kitchen_only_lavadora.obj</uri>
            </mesh>
          </geometry>
          <max_contacts>10</max_contacts>
          <surface>
            <contact>
              <ode/>
            </contact>
            <bounce/>
            <friction>
              <torsional>
                <ode/>
              </torsional>
              <ode/>
            </friction>
          </surface>
        </collision>
        <visual name='base_link_visual'>
          <pose>0 0 0 1.5714 -0 0</pose>
          <geometry>
            <mesh>
              <scale>100 100 100</scale>
              <uri>model://sink_furniture/meshes/kitchen_only_kitchen.obj</uri>
            </mesh>
          </geometry>
        </visual>
        <visual name='base_link_fixed_joint_lump__washer_link_visual_1'>
          <pose>-0.09 0.001 0.581 1.5714 -0 0</pose>
          <geometry>
            <mesh>
              <scale>1 1 1</scale>
              <uri>model://sink_furniture/meshes/kitchen_only_lavadora.obj</uri>
            </mesh>
          </geometry>
        </visual>
        <self_collide>0</self_collide>
        <enable_wind>0</enable_wind>
        <kinematic>0</kinematic>
      </link>
      <joint name='dishrack_1_joint' type='prismatic'>
        <pose relative_to='base_link'>-0.897 0.035 0.49 0 -0 0</pose>
        <parent>base_link</parent>
        <child>dishrack_1_link</child>
        <axis>
          <xyz>0 -1 0</xyz>
          <limit>
            <lower>0</lower>
            <upper>0.5</upper>
            <effort>0</effort>
            <velocity>0</velocity>
          </limit>
          <dynamics>
            <damping>0.5</damping>
            <friction>1</friction>
            <spring_reference>0</spring_reference>
            <spring_stiffness>0</spring_stiffness>
          </dynamics>
        </axis>
      </joint>
      <link name='dishrack_1_link'>
        <pose relative_to='dishrack_1_joint'>0 0 0 0 -0 0</pose>
        <inertial>
          <pose>-0 0.001017 0.024848 0 -0 0</pose>
          <mass>5</mass>
          <inertia>
            <ixx>0.0896811</ixx>
            <ixy>-4.20102e-09</ixy>
            <ixz>-2.01219e-09</ixz>
            <iyy>0.141374</iyy>
            <iyz>-0.0042403</iyz>
            <izz>0.0985203</izz>
          </inertia>
        </inertial>
        <collision name='dishrack_1_link_collision'>
          <pose>0 0 0 1.5714 -0 0</pose>
          <geometry>
            <mesh>
              <scale>1 1 1</scale>
              <uri>model://sink_furniture/meshes/kitchen_only_parte_de_abajo_lavavajillas.obj</uri>
            </mesh>
          </geometry>
          <max_contacts>10</max_contacts>
          <surface>
            <contact>
              <ode/>
            </contact>
            <bounce/>
            <friction>
              <torsional>
                <ode/>
              </torsional>
              <ode/>
            </friction>
          </surface>
        </collision>
        <collision name='dishrack_1_link_fixed_joint_lump__silverware_link_collision_1'>
          <pose>0 -0.01 0.05 1.5714 -0 0</pose>
          <geometry>
            <mesh>
              <scale>1 1 1</scale>
              <uri>model://sink_furniture/meshes/kitchen_only_cubiertos_lavavajillas.obj</uri>
            </mesh>
          </geometry>
          <max_contacts>10</max_contacts>
          <surface>
            <contact>
              <ode/>
            </contact>
            <bounce/>
            <friction>
              <torsional>
                <ode/>
              </torsional>
              <ode/>
            </friction>
          </surface>
        </collision>
        <visual name='dishrack_1_link_visual'>
          <pose>0 0 0 1.5714 -0 0</pose>
          <geometry>
            <mesh>
              <scale>1 1 1</scale>
              <uri>model://sink_furniture/meshes/kitchen_only_parte_de_abajo_lavavajillas.obj</uri>
            </mesh>
          </geometry>
        </visual>
        <visual name='dishrack_1_link_fixed_joint_lump__silverware_link_visual_1'>
          <pose>0 -0.01 0.05 1.5714 -0 0</pose>
          <geometry>
            <mesh>
              <scale>1 1 1</scale>
              <uri>model://sink_furniture/meshes/kitchen_only_cubiertos_lavavajillas.obj</uri>
            </mesh>
          </geometry>
        </visual>
        <self_collide>0</self_collide>
        <enable_wind>0</enable_wind>
        <kinematic>0</kinematic>
      </link>
      <joint name='dishrack_2_joint' type='prismatic'>
        <pose relative_to='base_link'>-0.897 0.035 0.792 0 -0 0</pose>
        <parent>base_link</parent>
        <child>dishrack_2_link</child>
        <axis>
          <xyz>0 -1 0</xyz>
          <limit>
            <lower>0</lower>
            <upper>0.5</upper>
            <effort>0</effort>
            <velocity>0</velocity>
          </limit>
          <dynamics>
            <damping>0.5</damping>
            <friction>1</friction>
            <spring_reference>0</spring_reference>
            <spring_stiffness>0</spring_stiffness>
          </dynamics>
        </axis>
      </joint>
      <link name='dishrack_2_link'>
        <pose relative_to='dishrack_2_joint'>0 0 0 0 -0 0</pose>
        <inertial>
          <pose>0.008706 -0.004417 0.026342 0 -0 0</pose>
          <mass>3</mass>
          <inertia>
            <ixx>0.0695101</ixx>
            <ixy>2.372e-05</ixy>
            <ixz>4.623e-05</ixz>
            <iyy>0.128744</iyy>
            <iyz>0.00035407</iyz>
            <izz>0.0707099</izz>
          </inertia>
        </inertial>
        <collision name='dishrack_2_link_collision'>
          <pose>0 0 0 1.5714 -0 0</pose>
          <geometry>
            <mesh>
              <scale>1 1 1</scale>
              <uri>model://sink_furniture/meshes/kitchen_only_parte_de_arriba_lavavajillas.obj</uri>
            </mesh>
          </geometry>
          <max_contacts>10</max_contacts>
          <surface>
            <contact>
              <ode/>
            </contact>
            <bounce/>
            <friction>
              <torsional>
                <ode/>
              </torsional>
              <ode/>
            </friction>
          </surface>
        </collision>
        <visual name='dishrack_2_link_visual'>
          <pose>0 0 0 1.5714 -0 0</pose>
          <geometry>
            <mesh>
              <scale>1 1 1</scale>
              <uri>model://sink_furniture/meshes/kitchen_only_parte_de_arriba_lavavajillas.obj</uri>
            </mesh>
          </geometry>
        </visual>
        <self_collide>0</self_collide>
        <enable_wind>0</enable_wind>
        <kinematic>0</kinematic>
      </link>
      <joint name='door_1_joint' type='revolute'>
        <pose relative_to='base_link'>-0.596 -0.325 0.594 0 -0 0</pose>
        <parent>base_link</parent>
        <child>door_1_link</child>
        <axis>
          <xyz>0 0 -1</xyz>
          <limit>
            <lower>0</lower>
            <upper>2</upper>
            <effort>0</effort>
            <velocity>0</velocity>
          </limit>
          <dynamics>
            <damping>0.5</damping>
            <friction>1</friction>
            <spring_reference>0</spring_reference>
            <spring_stiffness>0</spring_stiffness>
          </dynamics>
        </axis>
      </joint>
      <link name='door_1_link'>
        <pose relative_to='door_1_joint'>0 0 0 0 -0 0</pose>
        <inertial>
          <pose>0.234309 0.296772 0.013344 0 -0 0</pose>
          <mass>3</mass>
          <inertia>
            <ixx>0.146762</ixx>
            <ixy>-0.00813386</ixy>
            <ixz>-0.00130403</ixz>
            <iyy>0.079376</iyy>
            <iyz>-0.00166311</iyz>
            <izz>0.225484</izz>
          </inertia>
        </inertial>
        <collision name='door_1_link_collision'>
          <pose>0.3 0 0 1.5714 -0 0</pose>
          <geometry>
            <mesh>
              <scale>1 1 1</scale>
              <uri>model://sink_furniture/meshes/kitchen_only_armario_lavamanos.obj</uri>
            </mesh>
          </geometry>
          <max_contacts>10</max_contacts>
          <surface>
            <contact>
              <ode/>
            </contact>
            <bounce/>
            <friction>
              <torsional>
                <ode/>
              </torsional>
              <ode/>
            </friction>
          </surface>
        </collision>
        <visual name='door_1_link_visual'>
          <pose>0.3 0 0 1.5714 -0 0</pose>
          <geometry>
            <mesh>
              <scale>1 1 1</scale>
              <uri>model://sink_furniture/meshes/kitchen_only_armario_lavamanos.obj</uri>
            </mesh>
          </geometry>
        </visual>
        <self_collide>0</self_collide>
        <enable_wind>0</enable_wind>
        <kinematic>0</kinematic>
      </link>
      <joint name='door_2_joint' type='revolute'>
        <pose relative_to='base_link'>-0.899 -0.293 0.34 0 -0 0</pose>
        <parent>base_link</parent>
        <child>door_2_link</child>
        <axis>
          <xyz>1 0 0</xyz>
          <limit>
            <lower>0</lower>
            <upper>1.6</upper>
            <effort>0</effort>
            <velocity>0</velocity>
          </limit>
          <dynamics>
            <damping>0.5</damping>
            <friction>1</friction>
            <spring_reference>0</spring_reference>
            <spring_stiffness>0</spring_stiffness>
          </dynamics>
        </axis>
      </joint>
      <link name='door_2_link'>
        <pose relative_to='door_2_joint'>0 0 0 0 -0 0</pose>
        <inertial>
          <pose>0 0.354086 0.044429 0 -0 0</pose>
          <mass>8</mass>
          <inertia>
            <ixx>0.430657</ixx>
            <ixy>0</ixy>
            <ixz>0</ixz>
            <iyy>0.231769</iyy>
            <iyz>-0.00532904</iyz>
            <izz>0.650277</izz>
          </inertia>
        </inertial>
        <collision name='door_2_link_collision'>
          <pose>0 0 0.254 1.5714 -0 0</pose>
          <geometry>
            <mesh>
              <scale>1 1 1</scale>
              <uri>model://sink_furniture/meshes/kitchen_only_puerta_lavavajillas.obj</uri>
            </mesh>
          </geometry>
          <max_contacts>10</max_contacts>
          <surface>
            <contact>
              <ode/>
            </contact>
            <bounce/>
            <friction>
              <torsional>
                <ode/>
              </torsional>
              <ode/>
            </friction>
          </surface>
        </collision>
        <visual name='door_2_link_visual'>
          <pose>0 0 0.254 1.5714 -0 0</pose>
          <geometry>
            <mesh>
              <scale>1 1 1</scale>
              <uri>model://sink_furniture/meshes/kitchen_only_puerta_lavavajillas.obj</uri>
            </mesh>
          </geometry>
        </visual>
        <self_collide>0</self_collide>
        <enable_wind>0</enable_wind>
        <kinematic>0</kinematic>
      </link>
      <joint name='drawer_1_joint' type='prismatic'>
        <pose relative_to='base_link'>0.305 -0.068 0.895 0 -0 0</pose>
        <parent>base_link</parent>
        <child>drawer_1_link</child>
        <axis>
          <xyz>0 -1 0</xyz>
          <limit>
            <lower>0</lower>
            <upper>0.4</upper>
            <effort>100</effort>
            <velocity>100</velocity>
          </limit>
          <dynamics>
            <damping>0.5</damping>
            <friction>1</friction>
            <spring_reference>0</spring_reference>
            <spring_stiffness>0</spring_stiffness>
          </dynamics>
        </axis>
      </joint>
      <link name='drawer_1_link'>
        <pose relative_to='drawer_1_joint'>0 0 0 0 -0 0</pose>
        <inertial>
          <pose>0.005449 0.058284 0.255974 0 -0 0</pose>
          <mass>5</mass>
          <inertia>
            <ixx>0.133959</ixx>
            <ixy>6e-06</ixy>
            <ixz>0.00125108</ixz>
            <iyy>0.259147</iyy>
            <iyz>-0.00124005</iyz>
            <izz>0.149073</izz>
          </inertia>
        </inertial>
        <collision name='drawer_1_link_collision'>
          <pose>0 0 0 1.5714 -0 0</pose>
          <geometry>
            <mesh>
              <scale>1 1 1</scale>
              <uri>model://sink_furniture/meshes/kitchen_only_cajon_1.obj</uri>
            </mesh>
          </geometry>
          <max_contacts>10</max_contacts>
          <surface>
            <contact>
              <ode/>
            </contact>
            <bounce/>
            <friction>
              <torsional>
                <ode/>
              </torsional>
              <ode/>
            </friction>
          </surface>
        </collision>
        <visual name='drawer_1_link_visual'>
          <pose>0 0 0 1.5714 -0 0</pose>
          <geometry>
            <mesh>
              <scale>1 1 1</scale>
              <uri>model://sink_furniture/meshes/kitchen_only_cajon_1.obj</uri>
            </mesh>
          </geometry>
        </visual>
        <self_collide>0</self_collide>
        <enable_wind>0</enable_wind>
        <kinematic>0</kinematic>
      </link>
      <joint name='drawer_2_joint' type='prismatic'>
        <pose relative_to='base_link'>0.305 -0.068 0.694 0 -0 0</pose>
        <parent>base_link</parent>
        <child>drawer_2_link</child>
        <axis>
          <xyz>0 -1 0</xyz>
          <limit>
            <lower>0</lower>
            <upper>0.4</upper>
            <effort>0</effort>
            <velocity>0</velocity>
          </limit>
          <dynamics>
            <spring_reference>0</spring_reference>
            <spring_stiffness>0</spring_stiffness>
          </dynamics>
        </axis>
      </joint>
      <link name='drawer_2_link'>
        <pose relative_to='drawer_2_joint'>0 0 0 0 -0 0</pose>
        <inertial>
          <pose>0.005449 0.060122 0.255974 0 -0 0</pose>
          <mass>5</mass>
          <inertia>
            <ixx>0.133965</ixx>
            <ixy>5.99e-06</ixy>
            <ixz>0.00125106</ixz>
            <iyy>0.259148</iyy>
            <iyz>-0.00126118</iyz>
            <izz>0.149077</izz>
          </inertia>
        </inertial>
        <collision name='drawer_2_link_collision'>
          <pose>0 0 0 1.5714 -0 0</pose>
          <geometry>
            <mesh>
              <scale>1 1 1</scale>
              <uri>model://sink_furniture/meshes/kitchen_only_cajon_2.obj</uri>
            </mesh>
          </geometry>
          <max_contacts>10</max_contacts>
          <surface>
            <contact>
              <ode/>
            </contact>
            <bounce/>
            <friction>
              <torsional>
                <ode/>
              </torsional>
              <ode/>
            </friction>
          </surface>
        </collision>
        <visual name='drawer_2_link_visual'>
          <pose>0 0 0 1.5714 -0 0</pose>
          <geometry>
            <mesh>
              <scale>1 1 1</scale>
              <uri>model://sink_furniture/meshes/kitchen_only_cajon_2.obj</uri>
            </mesh>
          </geometry>
        </visual>
        <self_collide>0</self_collide>
        <enable_wind>0</enable_wind>
        <kinematic>0</kinematic>
      </link>
      <joint name='drawer_3_joint' type='prismatic'>
        <pose relative_to='base_link'>0.311 -0.068 0.392 0 -0 0</pose>
        <parent>base_link</parent>
        <child>drawer_3_link</child>
        <axis>
          <xyz>0 -1 0</xyz>
          <limit>
            <lower>0</lower>
            <upper>0.4</upper>
            <effort>0</effort>
            <velocity>0</velocity>
          </limit>
          <dynamics>
            <damping>0.5</damping>
            <friction>1</friction>
            <spring_reference>0</spring_reference>
            <spring_stiffness>0</spring_stiffness>
          </dynamics>
        </axis>
      </joint>
      <link name='drawer_3_link'>
        <pose relative_to='drawer_3_joint'>0 0 0 0 -0 0</pose>
        <inertial>
          <pose>0.005449 0.146757 0.255974 0 -0 0</pose>
          <mass>7</mass>
          <inertia>
            <ixx>0.229778</ixx>
            <ixy>0.00021958</ixy>
            <ixz>0.00169859</ixz>
            <iyy>0.358769</iyy>
            <iyz>-0.0238841</iyz>
            <izz>0.256006</izz>
          </inertia>
        </inertial>
        <collision name='drawer_3_link_collision'>
          <pose>0 0 0 1.5714 -0 0</pose>
          <geometry>
            <mesh>
              <scale>1 1 1</scale>
              <uri>model://sink_furniture/meshes/kitchen_only_cajon_grande.obj</uri>
            </mesh>
          </geometry>
          <max_contacts>10</max_contacts>
          <surface>
            <contact>
              <ode/>
            </contact>
            <bounce/>
            <friction>
              <torsional>
                <ode/>
              </torsional>
              <ode/>
            </friction>
          </surface>
        </collision>
        <visual name='drawer_3_link_visual'>
          <pose>0 0 0 1.5714 -0 0</pose>
          <geometry>
            <mesh>
              <scale>1 1 1</scale>
              <uri>model://sink_furniture/meshes/kitchen_only_cajon_grande.obj</uri>
            </mesh>
          </geometry>
        </visual>
        <self_collide>0</self_collide>
        <enable_wind>0</enable_wind>
        <kinematic>0</kinematic>
      </link>
      <pose>0 0 0 0 -0 0</pose>
    </model>
    <model name='kitchen_no_sink_walls'>
      <pose>-0.487707 -2.40386 0 0 -0 0</pose>
      <link name='Wall_0'>
        <collision name='Wall_0_Collision'>
          <geometry>
            <box>
              <size>4.27 0.15 2.5</size>
            </box>
          </geometry>
          <pose>0 0 1.25 0 -0 0</pose>
          <max_contacts>10</max_contacts>
          <surface>
            <contact>
              <ode/>
            </contact>
            <bounce/>
            <friction>
              <torsional>
                <ode/>
              </torsional>
              <ode/>
            </friction>
          </surface>
        </collision>
        <visual name='Wall_0_Visual'>
          <pose>0 0 1.25 0 -0 0</pose>
          <geometry>
            <box>
              <size>4.27 0.15 2.5</size>
            </box>
          </geometry>
          <material>
            <script>
              <uri>file://media/materials/scripts/gazebo.material</uri>
              <name>Gazebo/CeilingTiled</name>
            </script>
            <ambient>1 1 1 1</ambient>
          </material>
          <meta>
            <layer>0</layer>
          </meta>
        </visual>
        <pose>-2.82197 -0.790533 0 0 -0 1.5708</pose>
        <self_collide>0</self_collide>
        <enable_wind>0</enable_wind>
        <kinematic>0</kinematic>
      </link>
      <link name='Wall_11'>
        <collision name='Wall_11_Collision'>
          <geometry>
            <box>
              <size>2.34557 0.15 2.5</size>
            </box>
          </geometry>
          <pose>0 0 1.25 0 -0 0</pose>
          <max_contacts>10</max_contacts>
          <surface>
            <contact>
              <ode/>
            </contact>
            <bounce/>
            <friction>
              <torsional>
                <ode/>
              </torsional>
              <ode/>
            </friction>
          </surface>
        </collision>
        <visual name='Wall_11_Visual'>
          <pose>0 0 1.25 0 -0 0</pose>
          <geometry>
            <box>
              <size>2.34557 0.15 2.5</size>
            </box>
          </geometry>
          <material>
            <script>
              <uri>file://media/materials/scripts/gazebo.material</uri>
              <name>Gazebo/CeilingTiled</name>
            </script>
            <ambient>1 1 1 1</ambient>
          </material>
          <meta>
            <layer>0</layer>
          </meta>
        </visual>
        <pose>-2.04447 2.04447 0 0 -0 0.783788</pose>
        <self_collide>0</self_collide>
        <enable_wind>0</enable_wind>
        <kinematic>0</kinematic>
      </link>
      <link name='Wall_4'>
        <collision name='Wall_4_Collision'>
          <geometry>
            <box>
              <size>5.825 0.15 2.5</size>
            </box>
          </geometry>
          <pose>0 0 1.25 0 -0 0</pose>
          <max_contacts>10</max_contacts>
          <surface>
            <contact>
              <ode/>
            </contact>
            <bounce/>
            <friction>
              <torsional>
                <ode/>
              </torsional>
              <ode/>
            </friction>
          </surface>
        </collision>
        <visual name='Wall_4_Visual'>
          <pose>0 0 1.25 0 -0 0</pose>
          <geometry>
            <box>
              <size>5.825 0.15 2.5</size>
            </box>
          </geometry>
          <material>
            <script>
              <uri>file://media/materials/scripts/gazebo.material</uri>
              <name>Gazebo/CeilingTiled</name>
            </script>
            <ambient>1 1 1 1</ambient>
          </material>
          <meta>
            <layer>0</layer>
          </meta>
        </visual>
        <pose>0.015533 -2.85053 0 0 -0 0</pose>
        <self_collide>0</self_collide>
        <enable_wind>0</enable_wind>
        <kinematic>0</kinematic>
      </link>
      <link name='Wall_7'>
        <collision name='Wall_7_Collision'>
          <geometry>
            <box>
              <size>3.5 0.15 2.5</size>
            </box>
          </geometry>
          <pose>-1 0 1.25 0 -0 0</pose>
          <max_contacts>10</max_contacts>
          <surface>
            <contact>
              <ode/>
            </contact>
            <bounce/>
            <friction>
              <torsional>
                <ode/>
              </torsional>
              <ode/>
            </friction>
          </surface>
        </collision>
        <visual name='Wall_7_Visual'>
          <pose>-1 0 1.25 0 -0 0</pose>
          <geometry>
            <box>
              <size>3.5 0.15 2.5</size>
            </box>
          </geometry>
          <material>
            <script>
              <uri>file://media/materials/scripts/gazebo.material</uri>
              <name>Gazebo/CeilingTiled</name>
            </script>
            <ambient>1 1 1 1</ambient>
          </material>
          <meta>
            <layer>0</layer>
          </meta>
        </visual>
        <pose>2.85303 -0.015533 0 0 -0 1.5708</pose>
        <self_collide>0</self_collide>
        <enable_wind>0</enable_wind>
        <kinematic>0</kinematic>
      </link>
      <link name='Wall_8'>
        <collision name='Wall_8_Collision'>
          <geometry>
            <box>
              <size>2 0.15 2.5</size>
            </box>
          </geometry>
          <pose>3 0 1.25 0 -0 0</pose>
          <max_contacts>10</max_contacts>
          <surface>
            <contact>
              <ode/>
            </contact>
            <bounce/>
            <friction>
              <torsional>
                <ode/>
              </torsional>
              <ode/>
            </friction>
          </surface>
        </collision>
        <visual name='Wall_8_Visual'>
          <pose>3 0 1.25 0 -0 0</pose>
          <geometry>
            <box>
              <size>2 0.15 2.5</size>
            </box>
          </geometry>
          <material>
            <script>
              <uri>file://media/materials/scripts/gazebo.material</uri>
              <name>Gazebo/CeilingTiled</name>
            </script>
            <ambient>1 1 1 1</ambient>
          </material>
          <meta>
            <layer>0</layer>
          </meta>
        </visual>
        <pose>2.85303 -0.015533 0 0 -0 1.5708</pose>
        <self_collide>0</self_collide>
        <enable_wind>0</enable_wind>
        <kinematic>0</kinematic>
      </link>

      <link name='Wall_9'>
        <collision name='Wall_9_Collision'>
          <geometry>
            <box>
              <size>4.27 0.15 2.5</size>
            </box>
          </geometry>
          <pose>0 0 1.25 0 -0 0</pose>
          <max_contacts>10</max_contacts>
          <surface>
            <contact>
              <ode/>
            </contact>
            <bounce/>
            <friction>
              <torsional>
                <ode/>
              </torsional>
              <ode/>
            </friction>
          </surface>
        </collision>
        <visual name='Wall_9_Visual'>
          <pose>0 0 1.25 0 -0 0</pose>
          <geometry>
            <box>
              <size>4.27 0.15 2.5</size>
            </box>
          </geometry>
          <material>
            <script>
              <uri>file://media/materials/scripts/gazebo.material</uri>
              <name>Gazebo/CeilingTiled</name>
            </script>
            <ambient>1 1 1 1</ambient>
          </material>
          <meta>
            <layer>0</layer>
          </meta>
        </visual>
        <pose>0.793033 2.81947 0 0 -0 3.14159</pose>
        <self_collide>0</self_collide>
        <enable_wind>0</enable_wind>
        <kinematic>0</kinematic>
      </link>
      <link name='Wall_20'>
        <collision name='Wall_20_Collision'>
          <geometry>
            <box>
              <size>10 0.15 2.5</size>
            </box>
          </geometry>
          <pose>0 0 1.25 0 -0 0</pose>
          <max_contacts>10</max_contacts>
          <surface>
            <contact>
              <ode/>
            </contact>
            <bounce/>
            <friction>
              <torsional>
                <ode/>
              </torsional>
              <ode/>
            </friction>
          </surface>
        </collision>
        <visual name='Wall_20_Visual'>
          <pose>0 0 1.25 0 -0 0</pose>
          <geometry>
            <box>
              <size>10 0.15 2.5</size>
            </box>
          </geometry>
          <material>
            <script>
              <uri>file://media/materials/scripts/gazebo.material</uri>
              <name>Gazebo/CeilingTiled</name>
            </script>
            <ambient>1 1 1 1</ambient>
          </material>
          <meta>
            <layer>0</layer>
          </meta>
        </visual>
        <pose>6.5 -2.0 0 0 0 1.5708</pose>
        <self_collide>0</self_collide>
        <enable_wind>0</enable_wind>
        <kinematic>0</kinematic>
      </link>

      <link name='Wall_21'>
        <collision name='Wall_21_Collision'>
          <geometry>
            <box>
              <size>2.5 0.15 2.5</size>
            </box>
          </geometry>
          <pose>0 0 1.25 0 -0 0</pose>
          <max_contacts>10</max_contacts>
          <surface>
            <contact>
              <ode/>
            </contact>
            <bounce/>
            <friction>
              <torsional>
                <ode/>
              </torsional>
              <ode/>
            </friction>
          </surface>
        </collision>
        <visual name='Wall_21_Visual'>
          <pose>0 0 1.25 0 -0 0</pose>
          <geometry>
            <box>
              <size>2.5 0.15 2.5</size>
            </box>
          </geometry>
          <material>
            <script>
              <uri>file://media/materials/scripts/gazebo.material</uri>
              <name>Gazebo/CeilingTiled</name>
            </script>
            <ambient>1 1 1 1</ambient>
          </material>
          <meta>
            <layer>0</layer>
          </meta>
        </visual>
        <pose>4 4.0 0 0 -0 0</pose>
        <self_collide>0</self_collide>
        <enable_wind>0</enable_wind>
        <kinematic>0</kinematic>
      </link>
      <link name='Wall_22'>
        <collision name='Wall_22_Collision'>
          <geometry>
            <box>
              <size>2 0.15 2.5</size>
            </box>
          </geometry>
          <pose>0 0 1.25 0 -0 0</pose>
          <max_contacts>10</max_contacts>
          <surface>
            <contact>
              <ode/>
            </contact>
            <bounce/>
            <friction>
              <torsional>
                <ode/>
              </torsional>
              <ode/>
            </friction>
          </surface>
        </collision>
        <visual name='Wall_22_Visual'>
          <pose>0 0 1.25 0 -0 0</pose>
          <geometry>
            <box>
              <size>2 0.15 2.5</size>
            </box>
          </geometry>
          <material>
            <script>
              <uri>file://media/materials/scripts/gazebo.material</uri>
              <name>Gazebo/CeilingTiled</name>
            </script>
            <ambient>1 1 1 1</ambient>
          </material>
          <meta>
            <layer>0</layer>
          </meta>
        </visual>
        <pose>5.8 3.4 0 0 -0 -0.783788</pose>
        <self_collide>0</self_collide>
        <enable_wind>0</enable_wind>
        <kinematic>0</kinematic>
      </link>
      <link name='Wall_23'>
        <collision name='Wall_23_Collision'>
          <geometry>
            <box>
              <size>8.0 0.15 2.5</size>
            </box>
          </geometry>
          <pose>0 0 1.25 0 -0 0</pose>
          <max_contacts>10</max_contacts>
          <surface>
            <contact>
              <ode/>
            </contact>
            <bounce/>
            <friction>
              <torsional>
                <ode/>
              </torsional>
              <ode/>
            </friction>
          </surface>
        </collision>
        <visual name='Wall_23_Visual'>
          <pose>0 0 1.25 0 -0 0</pose>
          <geometry>
            <box>
              <size>8.0 0.15 2.5</size>
            </box>
          </geometry>
          <material>
            <script>
              <uri>file://media/materials/scripts/gazebo.material</uri>
              <name>Gazebo/CeilingTiled</name>
            </script>
            <ambient>1 1 1 1</ambient>
          </material>
          <meta>
            <layer>0</layer>
          </meta>
        </visual>
        <pose>3 -7.0 0 0 -0 0</pose>
        <self_collide>0</self_collide>
        <enable_wind>0</enable_wind>
        <kinematic>0</kinematic>
      </link>

      <link name='Wall_24'>
        <collision name='Wall_24_Collision'>
          <geometry>
            <box>
              <size>6 0.15 2.5</size>
            </box>
          </geometry>
          <pose>0 0 1.25 0 -0 0</pose>
          <max_contacts>10</max_contacts>
          <surface>
            <contact>
              <ode/>
            </contact>
            <bounce/>
            <friction>
              <torsional>
                <ode/>
              </torsional>
              <ode/>
            </friction>
          </surface>
        </collision>
        <visual name='Wall_24_Visual'>
          <pose>0 0 1.25 0 -0 0</pose>
          <geometry>
            <box>
              <size>6 0.15 2.5</size>
            </box>
          </geometry>
          <material>
            <script>
              <uri>file://media/materials/scripts/gazebo.material</uri>
              <name>Gazebo/CeilingTiled</name>
            </script>
            <ambient>1 1 1 1</ambient>
          </material>
          <meta>
            <layer>0</layer>
          </meta>
        </visual>
        <pose>0 -4.0 0 0 -0 1.5709</pose>
        <self_collide>0</self_collide>
        <enable_wind>0</enable_wind>
        <kinematic>0</kinematic>
      </link>
      <link name='Wall_30'>
        <collision name='Wall_30_Collision'>
          <geometry>
            <box>
              <size>2.0 0.15 2.5</size>
            </box>
          </geometry>
          <pose>0 0 1.25 0 -0 0</pose>
          <max_contacts>10</max_contacts>
          <surface>
            <contact>
              <ode/>
            </contact>
            <bounce/>
            <friction>
              <torsional>
                <ode/>
              </torsional>
              <ode/>
            </friction>
          </surface>
        </collision>
        <visual name='Wall_30_Visual'>
          <pose>0 0 1.25 0 -0 0</pose>
          <geometry>
            <box>
              <size>2.0 0.15 2.5</size>
            </box>
          </geometry>
          <material>
            <script>
              <uri>file://media/materials/scripts/gazebo.material</uri>
              <name>Gazebo/CeilingTiled</name>
            </script>
            <ambient>1 1 1 1</ambient>
          </material>
          <meta>
            <layer>0</layer>
          </meta>
        </visual>
        <pose>3.5 0.0 0 0 -0 0</pose>
        <self_collide>0</self_collide>
        <enable_wind>0</enable_wind>
        <kinematic>0</kinematic>
      </link>

      <static>1</static>
    </model>
   
    <state world_name='default'>
      <sim_time>188 295000000</sim_time>
      <real_time>192 442895997</real_time>
      <wall_time>1697801815 920733114</wall_time>
      <iterations>188295</iterations>
      <model name='ground_plane'>
        <pose>0 0 0 0 -0 0</pose>
        <scale>1 1 1</scale>
        <link name='link'>
          <pose>0 0 0 0 -0 0</pose>
          <velocity>0 0 0 0 -0 0</velocity>
          <acceleration>0 0 0 0 -0 0</acceleration>
          <wrench>0 0 0 0 -0 0</wrench>
        </link>
      </model>
      <model name='kitchen_no_sink_walls'>
        <pose>-0.487707 -2.40386 0 0 -0 0</pose>
        <scale>1 1 1</scale>
        <link name='Wall_0'>
          <pose>-3.30968 -3.19439 0 0 -0 1.5708</pose>
          <velocity>0 0 0 0 -0 0</velocity>
          <acceleration>0 0 0 0 -0 0</acceleration>
          <wrench>0 0 0 0 -0 0</wrench>
        </link>
        <link name='Wall_11'>
          <pose>-2.53218 -0.35939 0 0 -0 0.783788</pose>
          <velocity>0 0 0 0 -0 0</velocity>
          <acceleration>0 0 0 0 -0 0</acceleration>
          <wrench>0 0 0 0 -0 0</wrench>
        </link>
        <link name='Wall_4'>
          <pose>-0.472174 -5.25439 0 0 -0 0</pose>
          <velocity>0 0 0 0 -0 0</velocity>
          <acceleration>0 0 0 0 -0 0</acceleration>
          <wrench>0 0 0 0 -0 0</wrench>
        </link>
        <link name='Wall_7'>
          <pose>2.36532 -2.41939 0 0 -0 1.5708</pose>
          <velocity>0 0 0 0 -0 0</velocity>
          <acceleration>0 0 0 0 -0 0</acceleration>
          <wrench>0 0 0 0 -0 0</wrench>
        </link>
        <link name='Wall_8'>
          <pose>2.36532 -2.41939 0 0 -0 1.5708</pose>
          <velocity>0 0 0 0 -0 0</velocity>
          <acceleration>0 0 0 0 -0 0</acceleration>
          <wrench>0 0 0 0 -0 0</wrench>
        </link>
        <link name='Wall_9'>
          <pose>0.305326 0.41561 0 0 -0 3.14159</pose>
          <velocity>0 0 0 0 -0 0</velocity>
          <acceleration>0 0 0 0 -0 0</acceleration>
          <wrench>0 0 0 0 -0 0</wrench>
        </link>
      </model>
      <model name='sink_furniture'>
        <pose>-0 0 0 0 -0 0</pose>
        <scale>1 1 1</scale>
        <link name='base_link'>
          <pose>-0 0 0.01 0 -0 0</pose>
          <velocity>0 0 -0 0 -0 0</velocity>
          <acceleration>-0 0 0 -1e-06 0 0</acceleration>
          <wrench>-0 0 0 0 -0 0</wrench>
        </link>
        <link name='dishrack_1_link'>
          <pose>-0.897 0.034007 0.5 -0 -0 -0</pose>
          <velocity>-0 -5e-06 0 0 -0 0</velocity>
          <acceleration>-0 -8e-06 -1e-06 2e-06 -2e-06 1.5e-05</acceleration>
          <wrench>-0 -3.9e-05 -7e-06 0 -0 0</wrench>
        </link>
        <link name='dishrack_2_link'>
          <pose>-0.897 0.034853 0.802 0 -0 0</pose>
          <velocity>-0 -1e-06 0 0 -0 0</velocity>
          <acceleration>0 1e-06 -0 -1e-06 -0 -1e-06</acceleration>
          <wrench>0 3e-06 -0 0 -0 0</wrench>
        </link>
        <link name='door_1_link'>
          <pose>-0.596 -0.325 0.604 0 -0 0</pose>
          <velocity>0 -0 -0 0 -0 0</velocity>
          <acceleration>-1e-06 1e-06 -0 -1e-06 0 2e-06</acceleration>
          <wrench>-2e-06 4e-06 -0 0 -0 0</wrench>
        </link>
        <link name='door_2_link'>
          <pose>-0.899 -0.293 0.35 0 -0 0</pose>
          <velocity>0 -0 -0 1e-06 -0 0</velocity>
          <acceleration>0 3e-06 -1.9e-05 -5.5e-05 -0 -0</acceleration>
          <wrench>1e-06 2.4e-05 -0.000155 0 -0 0</wrench>
        </link>
        <link name='drawer_1_link'>
          <pose>0.305 -0.068 0.905 0 -0 0</pose>
          <velocity>0 -0 -0 0 -0 0</velocity>
          <acceleration>-0 1e-06 0 -2e-06 -0 -0</acceleration>
          <wrench>-0 7e-06 0 0 -0 0</wrench>
        </link>
        <link name='drawer_2_link'>
          <pose>0.305 -0.069784 0.704 0 -0 0</pose>
          <velocity>0 -1.7e-05 -0 0 -0 0</velocity>
          <acceleration>-0 -0 0 -1e-06 -0 -0</acceleration>
          <wrench>-0 -0 0 0 -0 0</wrench>
        </link>
        <link name='drawer_3_link'>
          <pose>0.311 -0.068002 0.402 0 -0 0</pose>
          <velocity>0 -0 -0 0 -0 0</velocity>
          <acceleration>0 0 -0 -1e-06 0 0</acceleration>
          <wrench>0 2e-06 -0 0 -0 0</wrench>
        </link>
      </model>
      <light name='sun'>
        <pose>0 0 10 0 -0 0</pose>
      </light>
    </state>

    <include>
      <uri>model://env_exam_pick_surface</uri>
      <pose>-0.8 -4.2 0.15 0 0 1.5709</pose>
      <static>1</static>
    </include>

    <include>
      <uri>model://env_exam_place_surface</uri>
      <pose>2.5 -9 0.15 0 0 0</pose>
      <static>1</static>
    </include>

    <include>
      <uri>model://env_exam_cylinder1</uri>
      0<pose>.0 -4.5 0.1 0 0 0</pose>
      <static>1</static>
    </include>


    <include>
      <uri>model://env_exam_cylinder2</uri>
      <pose>2.7 -6.4 0.1 0 0 0</pose>
      <static>1</static>
    </include>

    <include>
      <uri>model://aruco_cube_exam_id63</uri>
      <pose>-0.9 -4.2 1.0 0 0 0</pose>
      <static>0</static>
    </include>
    <include>
      <uri>model://aruco_cube_exam_id582</uri>
      <pose>-1.0 -4.4 1.0 0 0 0</pose>
      <static>0</static>
    </include>

    <include>
      <uri>model://ikea_ektorp_chair</uri>
      <pose>3.0 -4.0 0.0 0 0 0</pose>
      <static>0</static>
    </include>

    <include>
      <uri>model://bookshelf</uri>
      <pose>3.7 1.4 0.0 0 0 0</pose>
      <static>0</static>
    </include>

    <include>
      <uri>model://closet</uri>
      <pose>5.27 -4.48 0.0 0 0 0</pose>
      <static>0</static>
    </include>

    <include>
      <uri>model://sofa</uri>
      <pose>5.2 -5.6 0.0 0 0 -1.5709</pose>
      <static>0</static>
    </include>


  </world>
</sdf>
